"use client";

import * as React from "react";
import { Button } from "@/components/ui/button";
import {
  Card,
  CardContent,
  CardDescription,
  CardHeader,
  CardTitle,
} from "@/components/ui/card";
import { AlertTriangle, RefreshCw, Home } from "lucide-react";

interface ErrorBoundaryState {
  hasError: boolean;
  error: Error | null;
  errorInfo: React.ErrorInfo | null;
}

interface ErrorBoundaryProps {
  children: React.ReactNode;
  fallback?: React.ComponentType<{ error: Error; resetError: () => void }>;
}

export class ErrorBoundary extends React.Component<
  ErrorBoundaryProps,
  ErrorBoundaryState
> {
  constructor(props: ErrorBoundaryProps) {
    super(props);
    this.state = { hasError: false, error: null, errorInfo: null };
  }

  static getDerivedStateFromError(error: Error): ErrorBoundaryState {
    return { hasError: true, error, errorInfo: null };
  }

  override componentDidCatch(error: Error, errorInfo: React.ErrorInfo) {
    console.error("ErrorBoundary caught an error:", error, errorInfo);

    // Log error to analytics/monitoring service
    if (typeof window !== "undefined") {
      // Send error to analytics
      try {
        // Example: send to error tracking service
        // analytics.track('error', { error: error.message, stack: error.stack });
      } catch (analyticsError) {
        console.error("Failed to send error to analytics:", analyticsError);
      }
    }
  }

  resetError = () => {
    this.setState({ hasError: false, error: null, errorInfo: null });
  };

  override render() {
    if (this.state.hasError) {
      if (this.props.fallback) {
        const FallbackComponent = this.props.fallback;
        return (
          <FallbackComponent
            error={this.state.error!}
            resetError={this.resetError}
          />
        );
      }

      return (
        <DefaultErrorFallback
          error={this.state.error!}
          resetError={this.resetError}
        />
      );
    }

    return this.props.children;
  }
}

interface DefaultErrorFallbackProps {
  error: Error;
  resetError: () => void;
}

function DefaultErrorFallback({
  error,
  resetError,
}: DefaultErrorFallbackProps) {
  const handleReset = () => {
    resetError();
    window.location.reload();
  };

  const handleGoHome = () => {
    window.location.href = "/";
  };

  return (
    <div className="min-h-screen flex items-center justify-center bg-background p-4">
      <Card className="w-full max-w-md">
        <CardHeader className="text-center">
          <div className="mx-auto mb-4 flex h-12 w-12 items-center justify-center rounded-full bg-destructive/10">
            <AlertTriangle className="h-6 w-6 text-destructive" />
          </div>
          <CardTitle className="text-xl">Something went wrong</CardTitle>
          <CardDescription>
            We encountered an unexpected error. Please try again or contact
            support if the problem persists.
          </CardDescription>
        </CardHeader>
        <CardContent className="space-y-4">
          {process.env.NODE_ENV === "development" && (
            <details className="rounded-md bg-muted p-3 text-sm">
              <summary className="cursor-pointer font-medium">
                Error Details
              </summary>
              <pre className="mt-2 whitespace-pre-wrap text-xs">
                {error.message}
                {error.stack && `\n\n${error.stack}`}
              </pre>
            </details>
          )}
          <div className="flex flex-col space-y-2 sm:flex-row sm:space-x-2 sm:space-y-0">
            <Button onClick={handleReset} className="flex-1">
              <RefreshCw className="mr-2 h-4 w-4" />
              Try Again
            </Button>
            <Button variant="outline" onClick={handleGoHome} className="flex-1">
              <Home className="mr-2 h-4 w-4" />
              Go Home
            </Button>
          </div>
        </CardContent>
      </Card>
    </div>
  );
}

// Hook for functional components to handle errors
export function useErrorHandler() {
  const [error, setError] = React.useState<Error | null>(null);

  const handleError = React.useCallback((error: Error) => {
    console.error("Error caught by useErrorHandler:", error);
    setError(error);

    // Send error to analytics
    try {
      // analytics.track('error', { error: error.message, stack: error.stack });
    } catch (analyticsError) {
      console.error("Failed to send error to analytics:", analyticsError);
    }
  }, []);

  const clearError = React.useCallback(() => {
    setError(null);
  }, []);

  return { error, handleError, clearError };
}
